Workbook

Sheet Estructura
A1: FACTOR 1 | B1: CONDICIONES HABILITANTES
A2: PILAR 1: INSTITUCIONES | C2: INVERSA | D2: Año de corte | O2: Nueva serie | P2: Antigua serie
A3: INS-1 | B3: Desempeño administrativo | N3: 2005 | O3: 41671878 | P3: 41671878
A4: INS-1-1 | B4: Gestión de recursos | C4: No | D4: 2020-2022 | N4: 2006 | O4: 42170126 | P4: 42170126
A5: INS-1-2 | B5: Gestión de regalías | C5: No | D5: 2021-2023 | N5: 2007 | O5: 42658630 | P5: 42658630
A6: INS-1-3 | B6: Índice de Gobierno Digital para el Estado | C6: No | D6: 2022 | N6: 2008 | O6: 43134017 | P6: 43134017
A7: INS-2 | B7: Gestión fiscal | N7: 2009 | O7: 43608630 | P7: 43608630
A8: INS-2-1 | B8: Autonomía fiscal | C8: No | D8: 2017-2022 | N8: 2010 | O8: 44086292 | P8: 44086292
A9: INS-2-2 | B9: Capacidad local de recaudo | C9: No | D9: 2017-2022 | N9: 2011 | O9: 44553416 | P9: 44553416
A10: INS-2-3 | B10: Capacidad de ahorro | C10: No | D10: 2017-2022 | N10: 2012 | O10: 45001571 | P10: 45001571
A11: INS-3 | B11: Transparencia y contratación pública | N11: 2013 | O11: 45434942 | P11: 45434942
A12: INS-3-1 | B12: Índice de Gobierno Digital para la Sociedad | C12: No | D12: 2022 | N12: 2014 | O12: 45866010 | P12: 45866010
A13: INS-3-2 | B13: Transparencia en el uso de regalías | C13: No | D13: 2021-2023 | N13: 2015 | O13: 46313898 | P13: 46313898
A14: INS-3-3 | B14: Procesos de contratación en SECOP II | C14: No | D14: 2019-2022 | N14: 2016 | O14: 46830116 | P14: 46830116
A15: INS-4 | B15: Seguridad y justicia | N15: 2017 | O15: 47419200 | P15: 47419200
A16: INS-4-1 | B16: Tasa de homicidios | C16: Sí | D16: 2018-2023 | N16: 2018 | O16: 48258494 | P16: 48258494
A17: INS-4-2 | B17: Tasa de secuestro | C17: Sí | D17: 2018-2023 | N17: 2019 | O17: 49395678 | P17: 49395678
A18: INS-4-3 | B18: Tasa de extorsión | C18: Sí | D18: 2018-2023 | N18: 2020 | O18: 50407647 | P18: 50372424
A19: INS-4-4 | B19: Eficiencia de la justicia | C19: No | D19: 2017-2023 | N19: 2021 | O19: 51117378 | P19: 51049498
A20: INS-4-5 | B20: Productividad de jueces | C20: No | D20: 2017-2023 | N20: 2022 | O20: 51682692 | P20: 51609474
A21: INS-4-6 | B21: Eficiencia de los métodos de resolución de conflictos | C21: No | D21: 2018-2023 | N21: 2023 | O21: 52215503 | P21: 52156254
A22: PILAR 2: INFRAESTRUCTURA | N22: 2024 | O22: 52695952 | P22: 52691440
A23: INF-1 | B23: Infraestructura de servicios | N23: 2025 | O23: 53110609 | P23: 53216592
A24: INF-1-1 | B24: Cobertura de acueducto | C24: No | D24: 2018-2022 | N24: 2026 | O24: 53474637 | P24: 53732415
A25: INF-1-2 | B25: Cobertura efectiva de gas natural | C25: No | D25: 2018-2023 | N25: 2027 | O25: 53808013
A26: INF-1-3 | B26: Cobertura efectiva de GLP | C26: No | D26: 2018-2023
A27: INF-1-4 | B27: Cobertura de la energía eléctrica | C27: No | D27: 2018-2022 | N27: 2028 | O27: 54119568
A28: INF-1-5 | B28: Costo de la energía eléctrica | C28: Sí | D28: 2018-2023 | N28: 2029 | O28: 54416612
A29: INF-1-6 | B29: Cobertura de alcantarillado | C29: No | D29: 2018-2022 | N29: 2030 | O29: 54705567
A30: INF-2 | B30: Infraestructura vial | N30: 2031 | O30: 54986438
A31: INF-2-1 | B31: Red vial primaria por cada 100.000 habitantes | C31: No | D31: 2018-2022 | N31: 2032 | O31: 55255685
A32: INF-2-2 | B32: Red vial primaria por área | C32: No | D32: 2018-2022 | N32: 2033 | O32: 55512668
A33: INF-2-3 | B33: Porcentaje de vías primarias en buen estado | C33: No | D33: 2018-2022 | N33: 2034 | O33: 55757459
A34: INF-2-4 | B34: Red vial a cargo del departamento por cada 100.000 habitantes | C34: No | D34: 2018-2023 | N34: 2035 | O34: 55990158
A35: INF-2-5 | B35: Red vial a cargo del departamento por área | C35: No | D35: 2018-2023
A36: INF-2-6 | B36: Porcentaje de vías a cargo del departamento en buen estado | C36: No | D36: 2018-2023
A37: INF-3 | B37: Conectividad
A38: INF-3-1 | B38: Costo de transporte terrestre a mercado interno | C38: Sí | D38: 2018-2023
A39: INF-3-2 | B39: Costo de transporte terrestre a aduanas | C39: Sí | D39: 2018-2023
A40: INF-3-3 | B40: Pasajeros movilizados vía aérea | C40: No | D40: 2018-2023
...

Sheet Dato_original
A1: Departamento | B1: Año | C1: INS-1-1 | D1: INS-1-2 | E1: INS-1-3 | F1: INS-2-1 | G1: INS-2-2 | H1: INS-2-3 | I1: INS-3-1 | J1: INS-3-2 | K1: INS-3-3 | L1: INS-4-1 | M1: INS-4-2 | N1: INS-4-3 | O1: INS-4-4 | P1: INS-4-5 | Q1: INS-4-6 | R1: INF-1-1 | S1: INF-1-2 | T1: INF-1-3 | U1: INF-1-4 | V1: INF-1-5 | W1: INF-1-6 | X1: INF-2-1 | Y1: INF-2-2 | Z1: INF-2-3 | AA1: INF-2-4 | AB1: INF-2-5 | AC1: INF-2-6 | AD1: INF-3-1 | AE1: INF-3-2 | AF1: INF-3-3 | AG1: INF-3-4 | AH1: TIC-1-1 | AI1: TIC-1-2 | AJ1: TIC-1-3 | AK1: TIC-1-4 | AL1: TIC-2-1 | AM1: TIC-2-2 | AN1: TIC-2-3 | AO1: AMB-1-1 | AP1: AMB-1-2 | AQ1: AMB-1-3 | AR1: AMB-1-4 | AS1: AMB-2-1 | AT1: AMB-2-2 | AU1: SAL-1-1 | AV1: SAL-1-2 | AW1: SAL-1-3 | AX1: SAL-2-1 | AY1: SAL-2-2 | AZ1: SAL-2-3 | BA1: SAL-3-1 | BB1: SAL-3-2 | BC1: SAL-3-3 | BD1: SAL-3-4 | BE1: EDU-1-1 | BF1: EDU-1-2 | BG1: EDU-1-3 | BH1: EDU-1-4 | BI1: EDU-1-5 | BJ1: EDU-2-1 | BK1: EDU-2-2 | BL1: EDU-2-3 | BM1: EDU-2-4 | BN1: EDS-1-1 | BO1: EDS-1-2 | BP1: EDS-1-3 | BQ1: EDS-2-1 | BR1: EDS-2-2 | BS1: EDS-2-3 | BT1: EDS-2-4 | BU1: EDS-3-1 | BV1: EDS-3-2 | BW1: NEG-1-1 | BX1: NEG-1-2 | BY1: NEG-1-3 | BZ1: NEG-2-1 | CA1: NEG-2-2 | CB1: NEG-2-3 | CC1: LAB-1-1 | CD1: LAB-1-2 | CE1: LAB-1-3 | CF1: LAB-1-4 | CG1: LAB-1-5 | CH1: FIN-1-1 | CI1: FIN-1-2 | CJ1: FIN-1-3 | CK1: FIN-1-4 | CL1: TAM-1-1 | CM1: TAM-2-1 | CN1: TAM-2-2 | CO1: SOF-1-1 | CP1: SOF-1-2 | CQ1: INN-1-1 | CR1: INN-1-2 | CS1: INN-1-3 | CT1: INN-1-4 | CU1: INN-1-5 | CV1: INN-1-6 | CW1: INN-2-1 | CX1: INN-2-2 | CY1: INN-2-3 | CZ1: INN-2-4
A2: Amazonas | B2: 2019 | C2: 94.551979 | D2: 76.954873 | E2: 33.241429 | F2: 0.083040651 | G2: 0.017309501 | H2: 26.15 | I2: 45.35 | J2: 94.404236 | K2: 0 | L2: 10.445364 | M2: 0 | N2: 2.6113411 | O2: n/a | P2: n/a | Q2: 0.66666667 | R2: 0.22533666 | S2: - | T2: n/a | U2: 85.479294 | V2: 567.3488 | W2: 0.18499224 | X2: 26.204807 | Y2: 0.01830119 | Z2: 0.88012048 | AA2: 12.338586 | AB2: 0.0086171522 | AC2: 0.28042328 | AD2: NA | AE2: - | AF2: 247911 | AG2: 0.2282 | AH2: 0.0052342587 | AI2: 1.5219093 | AJ2: 0.10872453 | AK2: 0.30864158 | AL2: 426.645 | AM2: 41.288 | AN2: 0.5556 | AO2: 6.9221614e-05 | AP2: 20.921 | AQ2: 0.35538667 | AR2: 0.19517787 | AS2: 3.7426901 | AT2: 10.65 | AU2: 0.79731243 | AV2: 0.80639535 | AW2: 56.280361 | AX2: 14.502762 | AY2: 69.060773 | AZ2: 72.12 | BA2: 37.267922 | BB2: 7.0741293 | BC2: 1.1248137 | BD2: 257.21709 | BE2: 0.4599 | BF2: 0.7833 | BG2: 0.6151 | BH2: 0.3151 | BI2: 0.0487 | BJ2: 224 | BK2: 230 | BL2: 0.18372703 | BM2: 28.015748 | BN2: 5.301 | BO2: 25.298 | BP2: 4.422 | BQ2: 138.82334 | BR2: 47.058824 | BS2: 16.787265 | BT2: 8.4337349 | BU2: 0 | BV2: 0.46202532 | BW2: 0.026490066 | BX2: 0.1582474 | BY2: 0.0180783 | BZ2: 4.7 | CA2: 3.3294598 | CB2: 0.0314 | CC2: 60.972763 | CD2: 5.293581 | CE2: 39.110294 | CF2: 2.5024974 | CG2: 0.6046183 | CH2: 13.873275 | CI2: 43.246346 | CJ2: 0.0017239361 | CK2: 0.23181611 | CL2: 27.288739 | CM2: 0 | CN2: 9.4793981e-05 | CO2: 1 | CP2: 1 | CQ2: 5.2226821 | CR2: 0 | CS2: 235.02069 | CT2: 0.02356 | CU2: 0.44 | CV2: 37.9056 | CW2: 0 | CX2: 0 | CY2: 0 | CZ2: 186.40818
A3: Antioquia | B3: 2019 | C3: 143.55973 | D3: 69.434146 | E3: 83.688889 | F3: 0.4807036 | G3: 0.0094169316 | H3: 49.29 | I3: 67.65 | J3: 95.935148 | K3: 0.021478217 | L3: 38.987986 | M3: 0.21850752 | N3: 18.401455 | O3: 0.6267244 | P3: 633.50973 | Q3: 0.53897059 | R3: 0.86388918 | S3: 0.68041991 | T3: n/a | U3: 99.330783 | V3: 452.99494 | W3: 0.77727684 | X3: 32.509393 | Y3: 3.2743979 | Z3: 0.87803337 | AA3: 23.1937 | AB3: 2.3361064 | AC3: 0.75086135 | AD3: 373.3275 | AE3: 297.39888 | AF3: 8785527 | AG3: 0.5348 | AH3: 0.16616111 | AI3: 6.5211786 | AJ3: 0.42085284 | AK3: 0.71721344 | AL3: 5711.979 | AM3: 717.971 | AN3: 2.5395 | AO3: 0.0019680995 | AP3: 10.838 | AQ3: 0.50197328 | AR3: 0.18671402 | AS3: 4.5614035 | AT3: 6.8448 | AU3: 0.94387858 | AV3: 0.93167917 | AW3: 90.629114 | AX3: 9.1093644 | AY3: 49.450835 | AZ3: 76.03 | BA3: 33.361068 | BB3: 8.4893498 | BC3: 6.0154763 | BD3: 208.19085 | BE3: 0.6798 | BF3: 0.9189 | BG3: 0.8129 | BH3: 0.4383 | BI3: 0.0397 | BJ3: 252.58375 | BK3: 251 | BL3: 0.39197332 | BM3: 29.908373 | BN3: 36.191 | BO3: 189.794 | BP3: 20.056 | BQ3: 153.60075 | BR3: 11.213383 | BS3: 37.469734 | BT3: 32.632578 | BU3: 56.235707 | BV3: 0.60913972 | BW3: 0.036311914 | BX3: 0.0064338 | BY3: 0.0269354 | BZ3: 11.79 | CA3: 10.048849 | CB3: 0.0776 | CC3: 61.781702 | CD3: 11.861609 | CE3: 45.762608 | CF3: 8.664365 | CG3: 0.32600623 | CH3: 24.251797 | CI3: 93.268581 | CJ3: 0.034608815 | CK3: 0.61454705 | CL3: 32.556507 | CM3: 29.976 | CN3: 24.034845 | CO3: 0.175 | CP3: 0.098 | CQ3: 3.9019201 | CR3: 0.68673794 | CS3: 373.80394 | CT3: 0.01 | CU3: 1.04 | CV3: 21.37 | CW3: 14.292877 | CX3: 7.6228675 | CY3: 24.29789 | CZ3: 1898.4116
A4: Arauca | B4: 2019 | C4: 99.315437 | D4: 74.552247 | E4: 30.83625 | F4: 0.088665625 | G4: 0.0098706935 | H4: 37.19 | I4: 84.62 | J4: 94.906511 | K4: 0.060117411 | L4: 57.976764 | M4: 2.3523131 | N4: 42.71972 | O4: 0.49490215 | P4: 348.42857 | Q4: 0.5877193 | R4: 0.7182601 | S4: 0.063957275 | T4: n/a | U4: 95.114412 | V4: 557.21299 | W4: 0.53978742 | X4: 168.4492 | Y4: 1.8541859 | Z4: 0.51086394 | AA4: 64.61701 | AB4: 0.71126459 | AC4: 0 | AD4: 395.49172 | AE4: 419.23856 | AF4: 114012 | AG4: 0.1088 | AH4: 0.039728798 | AI4: 4.9541882 | AJ4: 0.16453447 | AK4: 0.60897068 | AL4: 556.646 | AM4: 164.19 | AN4: 0.375 | AO4: 0.0017308964 | AP4: 21.607 | AQ4: 0.166212 | AR4: 0.27352665 | AS4: 0.35087719 | AT4: 10.285714 | AU4: 1 | AV4: 1 | AW4: 81.41953 | AX4: 10.459795 | AY4: 65.37372 | AZ4: 75.48 | BA4: 30.609404 | BB4: 6.490422 | BC4: 1.1834271 | BD4: 215.12431 | BE4: 0.6166 | BF4: 0.9381 | BG4: 0.7465 | BH4: 0.3666 | BI4: 0.0263 | BJ4: 248.89507 | BK4: 252 | BL4: 0.54144107 | BM4: 28.163599 | BN4: 7.485 | BO4: 10.778 | BP4: 4.219 | BQ4: 133.81393 | BR4: 45.454545 | BS4: 1.0582011 | BT4: 2.4113475 | BU4: 30.179445 | BV4: 0.48094374 | BW4: 0.031512605 | BX4: 0.0814861 | BY4: 0.50010912 | BZ4: 4.35 | CA4: 3.8333321 | CB4: 0.0249 | CC4: 61.895839 | CD4: 18.969049 | CE4: 28.028531 | CF4: 14.110578 | CG4: 0.53325791 | CH4: 24.502962 | CI4: 45.893117 | CJ4: 0.00022401635 | CK4: 0.13635767 | CL4: 28.808006 | CM4: 26.984 | CN4: 25.744955 | CO4: 1 | CP4: 1 | CQ4: 0 | CR4: 0 | CS4: 3.8142608 | CT4: 0.003 | CU4: 0 | CV4: 0 | CW4: 0 | CX4: 0 | CY4: 0 | CZ4: 31.935873
A5: Atlántico | B5: 2019 | C5: 135.76416 | D5: 79.594878 | E5: 74.765 | F5: 0.46872423 | G5: 0.011018587 | H5: 66.21 | I5: 75.58 | J5: 96.298918 | K5: 0.18191705 | L5: 22.283424 | M5: 0.039439688 | N5: 5.9553929 | O5: 0.57405721 | P5: 383.14359 | Q5: 0.46442406 | R5: 0.98462606 | S5: 0.87842557 | T5: n/a | U5: 99.638348 | V5: 452.66841 | W5: 0.85891767 | X5: 14.652672 | Y5: 10.965791 | Z5: 1 | AA5: 16.529962 | AB5: 12.37072 | AC5: 0.7911338 | AD5: 196.79923 | AE5: 196.79923 | AF5: 2482372 | AG5: 0.3158 | AH5: 0.13042194 | AI5: 6.1121835 | AJ5: 0.42942046 | AK5: 0.76209119 | AL5: 5443.658 | AM5: 695.529 | AN5: 2.3784 | AO5: 0 | AP5: 1.683 | AQ5: 0.63590838 | AR5: 0.13330752 | AS5: 0.93567251 | AT5: 21.46087 | AU5: 0.9957191 | AV5: 0.99294562 | AW5: 89.972231 | AX5: 12.554883 | AY5: 73.573039 | AZ5: 77.42 | BA5: 42.661738 | BB5: 9.4406946 | BC5: 3.4642936 | BD5: 378.22661 | BE5: 0.6154 | BF5: 0.8902 | BG5: 0.7655 | BH5: 0.4927 | BI5: 0.0155 | BJ5: 248.4899 | BK5: 241 | BL5: 0.5035776 | BM5: 30.910148 | BN5: 39.378 | BO5: 207.419 | BP5: 18.95 | BQ5: 147.06064 | BR5: 13.395079 | BS5: 53.32355 | BT5: 28.352631 | BU5: 58.173619 | BV5: 0.49643485 | BW5: 0.014423077 | BX5: 0.0250715 | BY5: 0.0672318 | BZ5: 16.54 | CA5: 10.53 | CB5: 0.063 | CC5: 63.897616 | CD5: 7.521595 | CE5: 31.086066 | CF5: 12.83905 | CG5: 0.52357124 | CH5: 34.179478 | CI5: 65.294625 | CJ5: 0.024289586 | CK5: 0.57741188 | CL5: 31.435324 | CM5: 28.881 | CN5: 29.126133 | CO5: 0.127 | CP5: 0.04 | CQ5: 4.0228482 | CR5: 0.43383657 | CS5: 363.23953 | CT5: 0.005 | CU5: 1 | CV5: 22.09 | CW5: 5.6716235 | CX5: 1.2153479 | CY5: 0.81023193 | CZ5: 812.25751
A6: Bogotá, D.C. | B6: 2019 | C6: 161.39709 | D6: 79.6 | E6: 91.9025 | F6: 0.54928466 | G6: 0.034935851 | H6: 62.92 | I6: 48.215 | J6: 98.6 | K6: 0.31486151 | L6: 14.542872 | M6: 0.14839666 | N6: 10.25286 | O6: 0.53574517 | P6: 679.81404 | Q6: 0.36015982 | R6: 0.99570168 | S6: 0.96346458 | T6: n/a | U6: 99.894262 | V6: 475.98583 | W6: 0.99460532 | X6: - | Y6: - | Z6: - | AA6: - | AB6: - | AC6: - | AD6: 325.03334 | AE6: 226.57396 | AF6: 25686743 | AG6: 1 | AH6: 0.22346138 | AI6: 8.8035763 | AJ6: 0.63750727 | AK6: 0.87104408 | AL6: 10166.292 | AM6: 1601.455 | AN6: 2.7656 | AO6: 6.7894537e-05 | AP6: 36.427 | AQ6: 0.63111998 | AR6: 0.17577393 | AS6: 1.754386 | AT6: 4.2 | AU6: 0.92496506 | AV6: 0.88670345 | AW6: 88.39084 | AX6: 9.4075217 | AY6: 43.452756 | AZ6: 79.49 | BA6: 55.171692 | BB6: 13.942219 | BC6: 7.0441761 | BD6: 240.33513 | BE6: 0.7065 | BF6: 0.9781 | BG6: 0.8597 | BH6: 0.5601 | BI6: 0.0165 | BJ6: 272.38782 | BK6: 257 | BL6: 0.32906263 | BM6: 40.983516 | BN6: 79.512 | BO6: 539.09988 | BP6: 30.591 | BQ6: 155.69302 | BR6: 8.2291743 | BS6: 33.25359 | BT6: 36.889667 | BU6: 29.86135 | BV6: 0.69293538 | BW6: 0.077423018 | BX6: 0.0052625 | BY6: 0.0067017 | BZ6: 17.182 | CA6: 15.2912 | CB6: 0.0731 | CC6: 71.179768 | CD6: 10.597089 | CE6: 51.246018 | CF6: 7.8052914 | CG6: 0.31766841 | CH6: 57.462528 | CI6: 133.21161 | CJ6: 0.038261655 | CK6: 0.72267587 | CL6: 33.331571 | CM6: 29.349 | CN6: 32.451936 | CO6: 0.132 | CP6: 0.018 | CQ6: 6.043791 | CR6: 0.92594823 | CS6: 588.46019 | CT6: 0.01 | CU6: 1.79 | CV6: 18.7 | CW6: 16.601493 | CX6: 9.6925781 | CY6: 25.048644 | CZ6: 1955.9603
A7: Bolívar | B7: 2019 | C7: 111.78606 | D7: 71.624394 | E7: 52.02 | F7: 0.30215054 | G7: 0.008713199 | H7: 46.82 | I7: 97.67 | J7: 95.231565 | K7: 0.18785311 | L7: 19.322645 | M7: 0.048306612 | N7: 8.8884166 | O7: 0.54775499 | P7: 382.98851 | Q7: 0.34727626 | R7: 0.80527502 | S7: 0.88356823 | T7: 0.3745583 | U7: 95.802788 | V7: 447.10164 | W7: 0.46285066 | X7: 40.529537 | Y7: 3.229679 | Z7: 0.95758803 | AA7: 7.8256711 | AB7: 0.62360459 | AC7: 0.87962963 | AD7: 214.54526 | AE7: 219.53608 | AF7: 5259812 | AG7: 0.4566 | AH7: 0.082540332 | AI7: 6.1635568 | AJ7: 0.23990779 | AK7: 0.57425134 | AL7: 2573.871 | AM7: 484.638 | AN7: 1.4419 | AO7: 0.0010610434 | AP7: 0.157 | AQ7: 0.54956694 | AR7: 0.14292086 | AS7: 1.0526316 | AT7: 6.8695652 | AU7: 0.87835834 | AV7: 0.86419662 | AW7: 87.511508 | AX7: 11.750372 | AY7: 100.17598 | AZ7: 76.38 | BA7: 30.44893 | BB7: 7.0993189 | BC7: 2.6656599 | BD7: 256.99117 | BE7: 0.6974 | BF7: 0.9725 | BG7: 0.7938 | BH7: 0.4417 | BI7: 0.0275 | BJ7: 232.90635 | BK7: 228 | BL7: 0.12574215 | BM7: 26.412205 | BN7: 22.358 | BO7: 104.632 | BP7: 17.611 | BQ7: 144.47017 | BR7: 5.9440559 | BS7: 42.394084 | BT7: 22.918641 | BU7: 38.269486 | BV7: 0.41007498 | BW7: 0.061779242 | BX7: 0.3013539 | BY7: 0.012989 | BZ7: 10.47 | CA7: 6.45 | CB7: 0.0617 | CC7: 68.445475 | CD7: 5.1506881 | CE7: 23.400639 | CF7: 10.936752 | CG7: 0.64178857 | CH7: 25.678853 | CI7: 51.374402 | CJ7: 0.010198837 | CK7: 0.24369 | CL7: 31.179053 | CM7: 29.049 | CN7: 34.132082 | CO7: 0.099 | CP7: 0.087 | CQ7: 1.8839579 | CR7: 0.24153306 | CS7: 165.20861 | CT7: 0.002 | CU7: 1.03 | CV7: 22.49 | CW7: 0.98245773 | CX7: 0.49122886 | CY7: 1.4736866 | CZ7: 268.21096
A8: Boyacá | B8: 2019 | C8: 113.55077 | D8: 68.072861 | E8: 76.728889 | F8: 0.25142099 | G8: 0.011484815 | H8: 49.41 | I8: 47.675 | J8: 90.99082 | K8: 0.08329369 | L8: 7.5572379 | M8: 0.16428778 | N8: 15.853771 | O8: 0.68105995 | P8: 190.64173 | Q8: 0.64 | R8: 0.84987168 | S8: 0.92335332 | T8: 0.22335518 | U8: 98.538834 | V8: 460.14025 | W8: 0.630598 | X8: 105.65405 | Y8: 5.5466256 | Z8: 0.56716747 | AA8: 58.915816 | AB8: 3.0929622 | AC8: 0.43492507 | AD8: 178.88546 | AE8: 161.3445 | AF8: - | AG8: - | AH8: 0.082339614 | AI8: 5.3592886 | AJ8: 0.3320431 | AK8: 0.63096509 | AL8: 5677.143 | AM8: 729.528 | AN8: 2.5238 | AO8: 0.00023965025 | AP8: 16.473 | AQ8: 0.52525 | AR8: 0.21869638 | AS8: 2.6900585 | AT8: 22.46087 | AU8: 0.95690129 | AV8: 0.95007186 | AW8: 90.006123 | AX8: 8.3673469 | AY8: 68.027211 | AZ8: 77.4 | BA8: 24.096275 | BB8: 7.5501384 | BC8: 2.0142036 | BD8: 188.10951 | BE8: 0.7066 | BF8: 0.9285 | BG8: 0.8925 | BH8: 0.5796 | BI8: 0.0207 | BJ8: 262.60908 | BK8: 260 | BL8: 0.66293499 | BM8: 21.214755 | BN8: 46.094 | BO8: 537.732 | BP8: 14.687 | BQ8: 151.9658 | BR8: 9.257175 | BS8: 56.644877 | BT8: 17.095409 | BU8: 10.800781 | BV8: 0.55072464 | BW8: 0.025118544 | BX8: 0.2732924 | BY8: 0.0104808 | BZ8: 6.83 | CA8: 4.75 | CB8: 0.0257 | CC8: 60.249927 | CD8: 7.5286727 | CE8: 28.223997 | CF8: 6.421692 | CG8: 0.51945522 | CH8: 35.328795 | CI8: 65.031461 | CJ8: 0.0067533166 | CK8: 0.17766802 | CL8: 30.796903 | CM8: 27.395 | CN8: 6.1210477 | CO8: 0.35 | CP8: 0.648 | CQ8: 1.3143022 | CR8: 0.65715112 | CS8: 230.82433 | CT8: 0.003 | CU8: 0.92 | CV8: 17.77 | CW8: 0.8280442 | CX8: 0.8280442 | CY8: 0.8280442 | CZ8: 210.32323
A9: Caldas | B9: 2019 | C9: 131.8794 | D9: 73.765719 | E9: 81.273333 | F9: 0.31902021 | G9: 0.013035196 | H9: 42.76 | I9: 46.8 | J9: 93.857373 | K9: 0.065826071 | L9: 20.43566 | M9: 0.20034961 | N9: 10.017481 | O9: 0.57286077 | P9: 446.84559 | Q9: 0.57094134 | R9: 0.8906426 | S9: 0.7619908 | T9: n/a | U9: 99.708547 | V9: 499.88903 | W9: 0.80029131 | X9: 42.728261 | Y9: 5.4074163 | Z9: 0.88142179 | AA9: 49.038423 | AB9: 13.28106 | AC9: 0.78803181 | AD9: 240.45884 | AE9: 201.36414 | AF9: 217271 | AG9: 0.1268 | AH9: 0.12027 | AI9: 5.9453979 | AJ9: 0.41098517 | AK9: 0.70654343 | AL9: 6579.506 | AM9: 998.882 | AN9: 3.0588 | AO9: 0.00037414637 | AP9: 4.765 | AQ9: 0.45296047 | AR9: 0.14113618 | AS9: 0.11695906 | AT9: 6.4592593 | AU9: 0.9481336 | AV9: 0.97097861 | AW9: 93.420911 | AX9: 9.1447015 | AY9: 32.275417 | AZ9: 78.12 | BA9: 30.132271 | BB9: 8.8410416 | BC9: 4.4215337 | BD9: 261.25589 | BE9: 0.6568 | BF9: 0.8301 | BG9: 0.7781 | BH9: 0.4519 | BI9: 0.0296 | BJ9: 256.123 | BK9: 255.65906 | BL9: 0.36990395 | BM9: 22.375774 | BN9: 40.035 | BO9: 259.441 | BP9: 16.567 | BQ9: 151.44973 | BR9: 17.084363 | BS9: 66.337046 | BT9: 23.520386 | BU9: 49.375 | BV9: 0.55753791 | BW9: 0.03531218 | BX9: 0.05482 | BY9: 0.0405993 | BZ9: 5.77 | CA9: 5.09 | CB9: 0.0651 | CC9: 58.563257 | CD9: 10.477586 | CE9: 41.662948 | CF9: 4.8564997 | CG9: 0.32686599 | CH9: 28.217217 | CI9: 67.655382 | CJ9: 0.018416453 | CK9: 0.33294904 | CL9: 30.196277 | CM9: 28.241 | CN9: 23.826574 | CO9: 0.143 | CP9: 0.391 | CQ9: 6.2108379 | CR9: 0.90157325 | CS9: 419.73243 | CT9: 0.008 | CU9: 0.62 | CV9: 20.39 | CW9: 5.0435612 | CX9: 3.0261367 | CY9: 3.0261367 | CZ9: 743.42093
A10: Caquetá | B10: 2019 | C10: 94.699524 | D10: 70.913518 | E10: 42.105714 | F10: 0.17595467 | G10: 0.013861755 | H10: 41.09 | I10: 88.37 | J10: 97.465875 | K10: 0.12252461 | L10: 45.539494 | M10: 0.24884969 | N10: 33.345859 | O10: 0.037437164 | P10: 628.7 | Q10: 0.58580858 | R10: 0.68155708 | S10: 0.89457851 | T10: 0.82497467 | U10: 90.558367 | V10: 587.03222 | W10: 0.59367835 | X10: 148.94027 | Y10: 0.67275333 | Z10: 0.53255073 | AA10: 36.50625 | AB10: 0.16489631 | AC10: 0.072256305 | AD10: 456.23177 | AE10: 513.11381 | AF10: 110539 | AG10: 0.1192 | AH10: 0.039715869 | AI10: 5.4630733 | AJ10: 0.24430547 | AK10: 0.58371176 | AL10: 2023.8 | AM10: 234.835 | AN10: 2.25 | AO10: 0.0052399242 | AP10: 39.064 | AQ10: 0.17382988 | AR10: 0.14813036 | AS10: 0.81871345 | AT10: 17.35 | AU10: 0.81037484 | AV10: 0.79170594 | AW10: 78.99124 | AX10: 11.071132 | AY10: 55.35566 | AZ10: 73.21 | BA10: 14.58812 | BB10: 4.7001998 | BC10: 0.69252943 | BD10: 215.25498 | BE10: 0.5917 | BF10: 0.9089 | BG10: 0.6946 | BH10: 0.3222 | BI10: 0.055 | BJ10: 244 | BK10: 246 | BL10: 0.37330317 | BM10: 20.19491 | BN10: 26.117 | BO10: 91.249 | BP10: 4.092 | BQ10: 136.74031 | BR10: 3.9577836 | BS10: 0.57923403 | BT10: 8.1924577 | BU10: 3.3898305 | BV10: 0.35719348 | BW10: 0.028820961 | BX10: 0.044557 | BY10: 0.0787038 | BZ10: 5.33 | CA10: 2.75 | CB10: 0.0307 | CC10: 60.506879 | CD10: 8.3967707 | CE10: 18.383532 | CF10: 7.8190272 | CG10: 0.53438481 | CH10: 37.635071 | CI10: 47.610551 | CJ10: 0.0059094694 | CK10: 0.29206174 | CL10: 28.983461 | CM10: 0 | CN10: 0.061511893 | CO10: 1 | CP10: 1 | CQ10: 0 | CR10: 0 | CS10: 116.95936 | CT10: 0.005 | CU10: 1.19 | CV10: 16.07 | CW10: 2.4931501 | CX10: 0 | CY10: 0 | CZ10: 57.342452
A11: Casanare | B11: 2019 | C11: 119.77925 | D11: 75.583265 | E11: 73.7125 | F11: 0.16285019 | G11: 0.0069178998 | H11: 35.38 | I11: 51.36 | J11: 94.693843 | K11: 0.17021647 | L11: 12.841733 | M11: 0.47561973 | N11: 43.043586 | O11: 0.50776889 | P11: 285.2549 | Q11: 0.51093439 | R11: 0.86065757 | S11: 0.78211504 | T11: n/a | U11: 97.581804 | V11: 509.30231 | W11: 0.74504389 | X11: 117.65855 | Y11: 1.1295721 | Z11: 0.65166785 | AA11: 70.629401 | AB11: 1.0959229 | AC11: 0.76572912 | AD11: 250.42867 | AE11: 223.08726 | AF11: 322762 | AG11: 0.1456 | AH11: 0.091718181 | AI11: 5.3418619 | AJ11: 0.3459189 | AK11: 0.68286184 | AL11: 2228.75 | AM11: 154.595 | AN11: 1 | AO11: 0.00041995405 | AP11: 2.928 | AQ11: 0.39550892 | AR11: 0.27502573 | AS11: 2.2222222 | AT11: 3.2263158 | AU11: 0.8865173 | AV11: 0.89926491 | AW11: 80.596551 | AX11: 6.3664596 | AY11: 108.69565 | AZ11: 76.96 | BA11: 30.439545 | BB11: 6.903661 | BC11: 1.2538595 | BD11: 185.01608 | BE11: 0.7143 | BF11: 0.9101 | BG11: 0.7886 | BH11: 0.4409 | BI11: 0.0269 | BJ11: 256.54004 | BK11: 257 | BL11: 0.36454984 | BM11: 24.038238 | BN11: 18.655 | BO11: 56.17 | BP11: 7.018 | BQ11: 139.9098 | BR11: 1.6574586 | BS11: 10.600744 | BT11: 8.0123267 | BU11: 0 | BV11: 0.59469942 | BW11: 0.031607263 | BX11: 0.0281223 | BY11: 0.3033634 | BZ11: 9.63 | CA11: 7.65 | CB11: 0.0379 | CC11: 71.703718 | CD11: 11.43427 | CE11: 36.191358 | CF11: 6.8981206 | CG11: 0.42751285 | CH11: 41.244004 | CI11: 67.953078 | CJ11: 0.003258767 | CK11: 0.12949347 | CL11: 29.840037 | CM11: 29.006 | CN11: 30.841403 | CO11: 0.29 | CP11: 1 | CQ11: 0 | CR11: 0 | CS11: 30.915283 | CT11: 0 | CU11: 0 | CV11: 0 | CW11: 0 | CX11: 2.4315814 | CY11: 0 | CZ11: 124.01065
A12: Cauca | B12: 2019 | C12: 79.987688 | D12: 76.299137 | E12: 59.20875 | F12: 0.13714163 | G12: 0.0071091905 | H12: 46.39 | I12: 46.22 | J12: 95.568468 | K12: 0.11841672 | L12: 47.388575 | M12: 1.7070812 | N12: 31.205445 | O12: 0.54502968 | P12: 299.06818 | Q12: 0.6604534 | R12: 0.76631045 | S12: 0.7134298 | T12: 0.79145026 | U12: 96.265853 | V12: 500.24672 | W12: 0.45466039 | X12: 103.87323 | Y12: 5.1904292 | Z12: 0.53822147 | AA12: 13.939479 | AB12: 0.69654019 | AC12: 0 | AD12: 308.17985 | AE12: 234.61708 | AF12: 110207 | AG12: 0.1192 | AH12: 0.046679082 | AI12: 5.4009864 | AJ12: 0.22426921 | AK12: 0.5454322 | AL12: 3739.885 | AM12: 421.076 | AN12: 1.5556 | AO12: 0.00043182666 | AP12: 8.965 | AQ12: 0.22025081 | AR12: 0.10309208 | AS12: 2.6900585 | AT12: 12.22381 | AU12: 0.9520505 | AV12: 0.94953245 | AW12: 85.361561 | AX12: 11.767838 | AY12: 69.222577 | AZ12: 75.96 | BA12: 19.27642 | BB12: 5.3667226 | BC12: 1.3998933 | BD12: 153.36418 | BE12: 0.5516 | BF12: 0.8455 | BG12: 0.6621 | BH12: 0.3358 | BI12: 0.0258 | BJ12: 235.91948 | BK12: 243 | BL12: 0.30626866 | BM12: 24.14519 | BN12: 24.4 | BO12: 67.019 | BP12: 11.409 | BQ12: 145.66846 | BR12: 8.2398619 | BS12: 38.444478 | BT12: 13.543565 | BU12: 45.146809 | BV12: 0.41091854 | BW12: 0.035407725 | BX12: 0.5597757 | BY12: 0.240367 | BZ12: 3.07 | CA12: 2.02 | CB12: 0.0567 | CC12: 64.938012 | CD12: 9.4940086 | CE12: 19.978739 | CF12: 14.404556 | CG12: 0.67527521 | CH12: 20.350791 | CI12: 38.080115 | CJ12: 0.0078667276 | CK12: 0.14370684 | CL12: 30.436786 | CM12: 27.576 | CN12: 11.917225 | CO12: 0.191 | CP12: 0.244 | CQ12: 0.75111575 | CR12: 0 | CS12: 104.47337 | CT12: 0.003 | CU12: 1.55 | CV12: 20.9 | CW12: 2.0706263 | CX12: 1.3804175 | CY12: 0.69020877 | CZ12: 185.66616
A13: Cesar | B13: 2019 | C13: 106.64053 | D13: 69.578485 | E13: 40.0925 | F13: 0.18750214 | G13: 0.0069562247 | H13: 42.39 | I13: 88.37 | J13: 95.842515 | K13: 0.072043937 | L13: 20.823373 | M13: 0.083293491 | N13: 13.743426 | O13: 0.53119227 | P13: 593.32967 | Q13: 0.63091716 | R13: 0.8530805 | S13: 0.88634777 | T13: 0.046553647 | U13: 95.440166 | V13: 410.26724 | W13: 0.73088433 | X13: 55.631223 | Y13: 2.915931 | Z13: 0.90380712 | AA13: 29.58918 | AB13: 1.5509277 | AC13: 0.5911215 | AD13: 301.76062 | AE13: 256.5899 | AF13: 389395 | AG13: 0.2354 | AH13: 0.075523387 | AI13: 5.4660211 | AJ13: 0.25003847 | AK13: 0.65990108 | AL13: 2927.427 | AM13: 395.428 | AN13: 1.1579 | AO13: 0.00014879789 | AP13: 0.786 | AQ13: 0.41503033 | AR13: 0.36489591 | AS13: 3.5087719 | AT13: 16.568 | AU13: 0.95618853 | AV13: 0.9220092 | AW13: 86.823747 | AX13: 14.53375 | AY13: 73.156457 | AZ13: 75.66 | BA13: 31.489071 | BB13: 7.4461035 | BC13: 1.4899247 | BD13: 335.2563 | BE13: 0.5881 | BF13: 0.878 | BG13: 0.7127 | BH13: 0.3994 | BI13: 0.0398 | BJ13: 244.37976 | BK13: 243 | BL13: 0.29209979 | BM13: 31.993888 | BN13: 23.87 | BO13: 98.416 | BP13: 8.768 | BQ13: 140.84189 | BR13: 5.9563758 | BS13: 1.3627734 | BT13: 9.6908442 | BU13: 61.608911 | BV13: 0.37015465 | BW13: 0.015972618 | BX13: 0.0639779 | BY13: 0.0083807 | BZ13: 6.75 | CA13: 3.5 | CB13: 0.0414 | CC13: 62.029944 | CD13: 10.545526 | CE13: 21.584854 | CF13: 8.5164379 | CG13: 0.64146875 | CH13: 17.458446 | CI13: 45.509842 | CJ13: 0.0027748296 | CK13: 0.16786763 | CL13: 29.560006 | CM13: 29.683 | CN13: 65.027019 | CO13: 0.068 | CP13: 0.872 | CQ13: 0.49976095 | CR13: 0 | CS13: 45.81142 | CT13: 0.003 | CU13: 0.73 | CV13: 22.5 | CW13: 0 | CX13: 0 | CY13: 0.86027796 | CZ13: 86.888074
A14: Chocó | B14: 2019 | C14: 77.355501 | D14: 67.081743 | E14: 50.434286 | F14: 0.13090081 | G14: 0.015652709 | H14: 10.14 | I14: 48.255 | J14: 89.030192 | K14: 0.22572766 | L14: 39.63906 | M14: 2.2437204 | N14: 24.306971 | O14: 0.56148076 | P14: 172.56061 | Q14: 0.58498584 | R14: 0.35023394 | S14: 0.10309032 | T14: 0.57623143 | U14: 84.901817 | V14: 654.37009 | W14: 0.21905762 | X14: 52.152102 | Y14: 0.59944767 | Z14: 0.68050631 | AA14: 5.5294619 | AB14: 0.063556845 | AC14: 0.12278092 | AD14: 507.51043 | AE14: 453.4192 | AF14: 329654 | AG14: 0.0162 | AH14: 0.040219823 | AI14: 4.5260503 | AJ14: 0.12942524 | AK14: 0.41009819 | AL14: 1226.619 | AM14: 76.787 | AN14: 1 | AO14: 0.0010349102 | AP14: 8.492 | AQ14: 0.084316579 | AR14: 0.1488883 | AS14: 5.6140351 | AT14: 4.5233333 | AU14: 0.83313211 | AV14: 0.77321834 | AW14: 68.391837 | AX14: 25.5515 | AY14: 317.40993 | AZ14: 71.19 | BA14: 14.055427 | BB14: 3.1530158 | BC14: 0.42258902 | BD14: 182.67623 | BE14: 0.5599 | BF14: 0.8174 | BG14: 0.5112 | BH14: 0.2321 | BI14: 0.0316 | BJ14: 209 | BK14: 216 | BL14: 0.17443609 | BM14: 26.032617 | BN14: 24.216 | BO14: 39.287 | BP14: 2.031 | BQ14: 124.8599 | BR14: 3.248731 | BS14: 1.0039083 | BT14: 3.2324622 | BU14: 0 | BV14: 0.30136986 | BW14: 0.0046480744 | BX14: 0.0514227 | BY14: 0.0338902 | BZ14: 3.65 | CA14: 2.24 | CB14: 0.015 | CC14: 55.4474 | CD14: 7.8662978 | CE14: 17.929254 | CF14: 3.7313879 | CG14: 0.71902171 | CH14: 17.987918 | CI14: 27.745963 | CJ14: 0.0027319128 | CK14: 0.12753857 | CL14: 28.865675 | CM14: 25.549 | CN14: 13.31866 | CO14: 0.437 | CP14: 0.929 | CQ14: 0 | CR14: 0 | CS14: 29.916272 | CT14: 0.005 | CU14: 0.69 | CV14: 36.36 | CW14: 0 | CX14: 1.8979366 | CY14: 0 | CZ14: 58.836033
A15: Córdoba | B15: 2019 | C15: 82.444697 | D15: 63.659973 | E15: 30.57 | F15: 0.17985429 | G15: 0.012652246 | H15: 40.28 | I15: 45.545 | J15: 92.165109 | K15: 0.083404367 | L15: 21.010958 | M15: 0 | N15: 8.124237 | O15: 0.50530691 | P15: 427.20202 | Q15: 0.58462181 | R15: 0.7432796 | S15: 0.86791347 | T15: n/a | U15: 97.942677 | V15: 434.50409 | W15: 0.37236573 | X15: 49.420462 | Y15: 3.5253717 | Z15: 0.84312084 | AA15: 11.506902 | AB15: 0.82083624 | AC15: 0 | AD15: 246.43365 | AE15: 230.21704 | AF15: 925753 | AG15: 0.2496 | AH15: 0.048876331 | AI15: 4.8614073 | AJ15: 0.17345443 | AK15: 0.47804867 | AL15: 2193.125 | AM15: 270.307 | AN15: 1.3043 | AO15: 0.00055677171 | AP15: 25.393 | AQ15: 0.28746695 | AR15: 0.11419744 | AS15: 3.2748538 | AT15: 15.273333 | AU15: 0.88454324 | AV15: 0.90385222 | AW15: 88.343834 | AX15: 15.036748 | AY15: 108.74456 | AZ15: 76.53 | BA15: 16.541742 | BB15: 5.0055783 | BC15: 1.1322892 | BD15: 209.43723 | BE15: 0.5831 | BF15: 0.9071 | BG15: 0.7821 | BH15: 0.4356 | BI15: 0.0223 | BJ15: 237.14631 | BK15: 240 | BL15: 0.39566969 | BM15: 25.011018 | BN15: 22.539 | BO15: 36.925 | BP15: 3.239 | BQ15: 139.13119 | BR15: 8.5295657 | BS15: 72.890981 | BT15: 11.107449 | BU15: 40.794424 | BV15: 0.29819967 | BW15: 0.017821782 | BX15: 0.0834352 | BY15: 0.4388173 | BZ15: 3.6 | CA15: 2.43 | CB15: 0.0554 | CC15: 69.008985 | CD15: 8.6217907 | CE15: 16.956615 | CF15: 8.5494578 | CG15: 0.62315815 | CH15: 15.288362 | CI15: 32.940546 | CJ15: 0.0062545293 | CK15: 0.24143959 | CL15: 30.311118 | CM15: 27.275 | CN15: 9.2250847 | CO15: 0.222 | CP15: 0.588 | CQ15: 0.67235064 | CR15: 0.05602922 | CS15: 100.2923 | CT15: 0.004 | CU15: 0.83 | CV15: 31.75 | CW15: 0 | CX15: 0.56719792 | CY15: 0 | CZ15: 87.915678
A16: Cundinamarca | B16: 2019 | C16: 144.18284 | D16: 61.706289 | E16: 84.7875 | F16: 0.48655343 | G16: 0.020287608 | H16: 55.87 | I16: 55.4 | J16: 90.713432 | K16: 0.020422388 | L16: 13.600269 | M16: 0.10277281 | N16: 9.1125225 | O16: 0.48984797 | P16: 348.9359 | Q16: 0.65842261 | R16: 0.89980724 | S16: 0.83743364 | T16: 0.13056321 | U16: 99.419599 | V16: 461.79977 | W16: 0.74068375 | X16: 40.389989 | Y16: 5.2092431 | Z16: 0.88971076 | AA16: 70.213356 | AB16: 9.0556709 | AC16: 0.73542987 | AD16: 378.40007 | AE16: 309.41371 | AF16: - | AG16: - | AH16: 0.12298066 | AI16: 5.8441392 | AJ16: 0.40159293 | AK16: 0.73188396 | AL16: 3060.362 | AM16: 388.078 | AN16: 1.6129 | AO16: 0.00013032052 | AP16: 13.095 | AQ16: 0.58090073 | AR16: 0.25717516 | AS16: 8.9076023 | AT16: 10.960345 | AU16: 0.95109055 | AV16: 0.95088364 | AW16: 88.397775 | AX16: 9.3930838 | AY16: 64.297895 | AZ16: 78.61 | BA16: 14.097635 | BB16: 2.8845327 | BC16: 1.0893353 | BD16: 130.72701 | BE16: 0.67 | BF16: 0.9858 | BG16: 0.864 | BH16: 0.5034 | BI16: 0.0289 | BJ16: 264.56589 | BK16: 255 | BL16: 0.36553199 | BM16: 29.415754 | BN16: 17.112 | BO16: 85.783 | BP16: 15.235 | BQ16: 149.63025 | BR16: 8.6237981 | BS16: 25.010079 | BT16: 20.681937 | BU16: 20.133994 | BV16: 0.60675546 | BW16: 0.040355424 | BX16: 0.0644177 | BY16: 0.004294 | BZ16: 10.4 | CA16: 6.93 | CB16: 0.0783 | CC16: 71.705998 | CD16: 10.348636 | CE16: 38.911065 | CF16: 9.4360209 | CG16: 0.35166523 | CH16: 36.2003 | CI16: 58.193603 | CJ16: 0.0041558815 | CK16: 0.16290081 | CL16: 31.722889 | CM16: 28.937 | CN16: 25.310466 | CO16: 0.125 | CP16: 0.058 | CQ16: 0.75366728 | CR16: 0.20554562 | CS16: 88.727193 | CT16: 0.006 | CU16: 0.92 | CV16: 24.05 | CW16: 3.9664153 | CX16: 3.9664153 | CY16: 8.653997 | CZ16: 644.36219
A17: Guainía | B17: 2019 | C17: 99.162656 | D17: 74.790565 | E17: 45.51375 | F17: 0.072117949 | G17: 0.031187739 | H17: 58.76 | I17: 41.86 | J17: 100 | K17: 0.0011648224 | L17: 6.2351914 | M17: 0 | N17: 39.489546 | O17: n/a | P17: n/a | Q17: 0.95238095 | R17: 0.15504416 | S17: - | T17: n/a | U17: 65.588954 | V17: 848.60133 | W17: 0.21133375 | X17: - | Y17: - | Z17: - | AA17: 37.587971 | AB17: 0.02706055 | AC17: 0 | AD17: NA | AE17: - | AF17: 50938 | AG17: 0.0064 | AH17: 0.0087196391 | AI17: 1.1717185 | AJ17: 0.13831799 | AK17: 0.29481309 | AL17: 2086.923 | AM17: 172.315 | AN17: 2.6667 | AO17: 0.00031676615 | AP17: 15.178 | AQ17: 0.040778302 | AR17: 0.17142291 | AS17: 1.6374269 | AT17: 0 | AU17: 0.99886364 | AV17: 0.93277311 | AW17: 33.413462 | AX17: 21.608643 | AY17: 0 | AZ17: 72.3 | BA17: 28.017531 | BB17: 4.4273512 | BC17: 0.58136935 | BD17: 108.07665 | BE17: 0.464 | BF17: 0.6195 | BG17: 0.2893 | BH17: 0.0679 | BI17: 0.0714 | BJ17: 225 | BK17: 246 | BL17: 0.18684211 | BM17: 31.347938 | BN17: 3.954 | BO17: 17.297 | BP17: 7.908 | BQ17: 133.45161 | BR17: 0 | BS17: 0 | BT17: 0 | BU17: 0 | BV17: 0.39939024 | BW17: 0 | BX17: 0.2112118 | BY17: 0.0284206 | BZ17: 3.95 | CA17: 1.62 | CB17: 0.0128 | CC17: 56.630991 | CD17: 12.181499 | CE17: 34.456794 | CF17: 12.264845 | CG17: 0.57186505 | CH17: 9.1611046 | CI17: 63.386119 | CJ17: 0 | CK17: 0.065242378 | CL17: 26.548902 | CM17: 0 | CN17: 0.27013891 | CO17: 1 | CP17: 1 | CQ17: 0 | CR17: 0 | CS17: 83.135886 | CT17: 0.02 | CU17: 0 | CV17: 0 | CW17: 0 | CX17: 0 | CY17: 0 | CZ17: 0
A18: Guaviare | B18: 2019 | C18: 132.91686 | D18: 75.671267 | E18: 65.67875 | F18: 0.12734789 | G18: 0.030977582 | H18: 46.74 | I18: 49.36 | J18: 95.850461 | K18: 0.00038729667 | L18: 33.829908 | M18: 0 | N18: 47.120229 | O18: 0.55917933 | P18: n/a | Q18: 0 | R18: 0.45135703 | S18: 0.37061619 | T18: n/a | U18: 83.954403 | V18: 679.44129 | W18: 0.42074713 | X18: 173.71658 | Y18: 0.26894875 | Z18: 0.57428791 | AA18: 0 | AB18: 0 | AC18: 0 | AD18: 500.67292 | AE18: 299.93078 | AF18: 26677 | AG18: 0.021 | AH18: 0.015253006 | AI18: 6.263752 | AJ18: 0.24444291 | AK18: 0.5164703 | AL18: 4937.816 | AM18: 209.334 | AN18: 1.4 | AO18: 0.0064015139 | AP18: 36.642 | AQ18: 0.15845195 | AR18: 0.16239682 | AS18: 2.6900585 | AT18: 4 | AU18: 0.94553377 | AV18: 0.93489393 | AW18: 65.757819 | AX18: 11.128776 | AY18: 0 | AZ18: 75.29 | BA18: 24.988578 | BB18: 6.8150668 | BC18: 0.30458399 | BD18: 166.73312 | BE18: 0.4244 | BF18: 0.821 | BG18: 0.665 | BH18: 0.3114 | BI18: 0.0336 | BJ18: 237 | BK18: 237 | BL18: 0.38875 | BM18: 29.108073 | BN18: 7.137 | BO18: 7.453 | BP18: 19.425 | BQ18: 138.07665 | BR18: 0 | BS18: 0 | BT18: 1.6806723 | BU18: 0 | BV18: 0.43478261 | BW18: 0.070886076 | BX18: 0.1950994 | BY18: 0.0403202 | BZ18: 6.89 | CA18: 2.92 | CB18: 0.0124 | CC18: 85.349123 | CD18: 10.821974 | CE18: 27.266439 | CF18: 13.337413 | CG18: 0.45346824 | CH18: 38.400261 | CI18: 51.284775 | CJ18: 0 | CK18: 0.18744863 | CL18: 27.353604 | CM18: 0 | CN18: 2.4022698e-05 | CO18: 1 | CP18: 1 | CQ18: 0 | CR18: 0 | CS18: 0 | CT18: 0.018 | CU18: 0 | CV18: 0 | CW18: 0 | CX18: 0 | CY18: 0 | CZ18: 12.42128
A19: Huila | B19: 2019 | C19: 113.84122 | D19: 68.986949 | E19: 57.535 | F19: 0.25605126 | G19: 0.011425822 | H19: 38.8 | I19: 48.835 | J19: 97.665056 | K19: 0.088508876 | L19: 21.719651 | M19: 0.36350881 | N19: 14.085966 | O19: 0.38740125 | P19: 486.32558 | Q19: 0.53862661 | R19: 0.82767957 | S19: 0.91439499 | T19: 0.87716493 | U19: 98.754414 | V19: 460.5719 | W19: 0.64989598 | X19: 89.678713 | Y19: 4.9613474 | Z19: 0.77159388 | AA19: 46.399173 | AB19: 2.5669683 | AC19: 0.65507178 | AD19: 241.10413 | AE19: 193.49194 | AF19: 262455 | AG19: 0.14 | AH19: 0.080902393 | AI19: 5.1347515 | AJ19: 0.30518504 | AK19: 0.6537008 | AL19: 3910.413 | AM19: 633.732 | AN19: 1.1852 | AO19: 0.00024278618 | AP19: 22.015 | AQ19: 0.34156988 | AR19: 0.17138675 | AS19: 5.1461988 | AT19: 14.3 | AU19: 0.93416396 | AV19: 0.93473965 | AW19: 90.706301 | AX19: 9.2945299 | AY19: 50.789781 | AZ19: 75.36 | BA19: 26.955553 | BB19: 8.5434987 | BC19: 3.3037966 | BD19: 224.64844 | BE19: 0.7097 | BF19: 0.924 | BG19: 0.8128 | BH19: 0.4475 | BI19: 0.0421 | BJ19: 256.7725 | BK19: 261 | BL19: 0.50051885 | BM19: 25.52213 | BN19: 26.603 | BO19: 59.449 | BP19: 13.957 | BQ19: 142.47452 | BR19: 4.2132982 | BS19: 40.684351 | BT19: 11.104319 | BU19: 12.659303 | BV19: 0.39900058 | BW19: 0.0093879084 | BX19: 0.0217237 | BY19: 0.0206157 | BZ19: 5.4 | CA19: 4.64 | CB19: 0.0345 | CC19: 63.319322 | CD19: 10.174818 | CE19: 24.03926 | CF19: 10.688051 | CG19: 0.64334497 | CH19: 32.570266 | CI19: 99.087312 | CJ19: 0.011914275 | CK19: 0.31019865 | CL19: 30.260103 | CM19: 28.011 | CN19: 9.409226 | CO19: 0.311 | CP19: 0.762 | CQ19: 0.72701761 | CR19: 0 | CS19: 89.059657 | CT19: 0.003 | CU19: 0.74 | CV19: 19.18 | CW19: 1.8405123 | CX19: 0.92025613 | CY19: 0 | CZ19: 219.02096
A20: La Guajira | B20: 2019 | C20: 76.709381 | D20: 65.232035 | E20: 53.98625 | F20: 0.11866052 | G20: 0.0058112896 | H20: 25.83 | I20: 47.095 | J20: 92.364475 | K20: 0.040539112 | L20: 25.892614 | M20: 0.56782048 | N20: 11.015717 | O20: 0.48746183 | P20: 185.78846 | Q20: 0.16783217 | R20: 0.55438784 | S20: 0.80263243 | T20: n/a | U20: 68.453627 | V20: 482.96905 | W20: 0.38246283 | X20: 42.692718 | Y20: 1.8032185 | Z20: 1 | AA20: 27.430385 | AB20: 1.1585812 | AC20: 0.19679061 | AD20: 128.14046 | AE20: 173.82128 | AF20: 170019 | AG20: 0.218 | AH20: 0.034460563 | AI20: 4.3067936 | AJ20: 0.11015511 | AK20: 0.40610938 | AL20: 1585.219 | AM20: 126.729 | AN20: 1.3636 | AO20: 0.00028213702 | AP20: 13.791 | AQ20: 0.28648286 | AR20: 0.13585629 | AS20: 3.0409357 | AT20: 17.106667 | AU20: 0.91173446 | AV20: 0.86201477 | AW20: 73.227855 | AX20: 16.179216 | AY20: 175.36912 | AZ20: 69.75 | BA20: 22.3119 | BB20: 5.9888173 | BC20: 0.61626352 | BD20: 217.9295 | BE20: 0.6637 | BF20: 0.9009 | BG20: 0.5654 | BH20: 0.2325 | BI20: 0.0277 | BJ20: 229.45375 | BK20: 232.9507 | BL20: 0.33876501 | BM20: 26.31365 | BN20: 16.83 | BO20: 8.865 | BP20: 7.085 | BQ20: 130.70199 | BR20: 6.2845304 | BS20: 2.786617 | BT20: 3.7383178 | BU20: 0 | BV20: 0.39 | BW20: 0.015907448 | BX20: 0.0556425 | BY20: 0.0077778 | BZ20: 4.52 | CA20: 1.97 | CB20: 0.0271 | CC20: 75.908155 | CD20: 3.8821058 | CE20: 18.140438 | CF20: 16.587419 | CG20: 0.73925882 | CH20: 13.359468 | CI20: 33.200011 | CJ20: 0.0029200102 | CK20: 0.091696286 | CL20: 28.948272 | CM20: 29.431 | CN20: 68.271639 | CO20: 0.175 | CP20: 0.989 | CQ20: 0.79494867 | CR20: 0 | CS20: 104.47897 | CT20: 0.003 | CU20: 0.8 | CV20: 18.92 | CW20: 0 | CX20: 0 | CY20: 0 | CZ20: 68.556947
A21: Magdalena | B21: 2019 | C21: 100.34918 | D21: 72.174371 | E21: 85.067778 | F21: 0.25072583 | G21: 0.014906462 | H21: 54.24 | I21: 61.96 | J21: 95.051949 | K21: 0.058553387 | L21: 16.545606 | M21: 0.52170828 | N21: 10.061517 | O21: 0.54621728 | P21: 298.32759 | Q21: 0.46863237 | R21: 0.7937076 | S21: 0.82005417 | T21: n/a | U21: 94.98991 | V21: 419.11668 | W21: 0.50282141 | X21: 48.054401 | Y21: 2.7806107 | Z21: 0.90956275 | AA21: 10.482671 | AB21: 0.60656729 | AC21: 0.74879587 | AD21: 173.93865 | AE21: 194.40458 | AF21: 1985735 | AG21: 0.2664 | AH21: 0.069337256 | AI21: 6.3865512 | AJ21: 0.24077879 | AK21: 0.56539173 | AL21: 2732.049 | AM21: 449.495 | AN21: 1.8125 | AO21: 0.00021760428 | AP21: 14.42 | AQ21: 0.45183848 | AR21: 0.081712686 | AS21: 1.0526316 | AT21: 9.4433333 | AU21: 0.91451978 | AV21: 0.88861583 | AW21: 85.787343 | AX21: 12.826522 | AY21: 110.79388 | AZ21: 75.39 | BA21: 20.32759 | BB21: 5.8922127 | BC21: 1.1386744 | BD21: 246.54443 | BE21: 0.6236 | BF21: 0.917 | BG21: 0.7392 | BH21: 0.4066 | BI21: 0.0326 | BJ21: 229.55982 | BK21: 228 | BL21: 0.15677301 | BM21: 28.531008 | BN21: 22.233 | BO21: 73.248 | BP21: 8.968 | BQ21: 143.5866 | BR21: 7.7883175 | BS21: 63.50553 | BT21: 16.176471 | BU21: 44.0174 | BV21: 0.39268978 | BW21: 0.027138158 | BX21: 0.0680279 | BY21: 0.0347208 | BZ21: 7.29 | CA21: 4.26 | CB21: 0.0551 | CC21: 62.388377 | CD21: 6.6666976 | CE21: 22.85422 | CF21: 9.9422449 | CG21: 0.65862451 | CH21: 18.637647 | CI21: 40.830574 | CJ21: 0.0060638137 | CK21: 0.30320689 | CL21: 29.998534 | CM21: 28.143 | CN21: 19.800018 | CO21: 0.188 | CP21: 0.28 | CQ21: 1.7141844 | CR21: 0.22358926 | CS21: 122.97409 | CT21: 0.005 | CU21: 0.71 | CV21: 25.64 | CW21: 0 | CX21: 0 | CY21: 0.76379082 | CZ21: 112.27725
A22: Meta | B22: 2019 | C22: 108.80451 | D22: 74.514372 | E22: 77.167778 | F22: 0.31470151 | G22: 0.0079748972 | H22: 54.89 | I22: 55.98 | J22: 97.236611 | K22: 0.08732341 | L22: 26.545557 | M22: 0.48089778 | N22: 44.146416 | O22: 0.57823579 | P22: 421.03623 | Q22: 0.62216359 | R22: 0.79842132 | S22: 0.82833083 | T22: 0.096083551 | U22: 97.409934 | V22: 490.8055 | W22: 0.79127854 | X22: 117.84208 | Y22: 1.4307585 | Z22: 0.79592672 | AA22: 4.901214 | AB22: 0.059507211 | AC22: 0.21005122 | AD22: 304.57366 | AE22: 237.8313 | AF22: 114688 | AG22: 0.2742 | AH22: 0.11247172 | AI22: 5.390237 | AJ22: 0.35936299 | AK22: 0.76909465 | AL22: 2079.993 | AM22: 414.277 | AN22: 1.24 | AO22: 0.0052980927 | AP22: 14.735 | AQ22: 0.51353164 | AR22: 0.20131139 | AS22: 3.625731 | AT22: 11.503448 | AU22: 0.85794847 | AV22: 0.84628389 | AW22: 82.145917 | AX22: 8.5637707 | AY22: 52.297836 | AZ22: 75.66 | BA22: 25.129575 | BB22: 6.2440712 | BC22: 1.6772294 | BD22: 247.18146 | BE22: 0.6524 | BF22: 0.9104 | BG22: 0.7831 | BH22: 0.4329 | BI22: 0.0447 | BJ22: 254.73524 | BK22: 254 | BL22: 0.38631634 | BM22: 30.975406 | BN22: 25.641 | BO22: 68.888 | BP22: 7.057 | BQ22: 143.60104 | BR22: 4.9056604 | BS22: 15.45029 | BT22: 12.656187 | BU22: 43.835616 | BV22: 0.49344978 | BW22: 0.036977492 | BX22: 0.010947 | BY22: 0.0504832 | BZ22: 9.87 | CA22: 6.48 | CB22: 0.0429 | CC22: 64.740838 | CD22: 12.167164 | CE22: 29.692489 | CF22: 9.4557911 | CG22: 0.43433329 | CH22: 42.071754 | CI22: 67.743124 | CJ22: 0.0056091314 | CK22: 0.15929475 | CL22: 30.955776 | CM22: 28.376 | CN22: 8.4175654 | CO22: 0.387 | CP22: 1 | CQ22: 0.38471822 | CR22: 0.096179556 | CS22: 65.402098 | CT22: 0.002 | CU22: 0.96 | CV22: 20 | CW22: 1.9570563 | CX22: 0.97852816 | CY22: 0 | CZ22: 209.40503
A23: Nariño | B23: 2019 | C23: 93.264191 | D23: 71.544247 | E23: 57.18 | F23: 0.19145586 | G23: 0.015436176 | H23: 53.64 | I23: 45.64 | J23: 94.25715 | K23: 0.032227976 | L23: 40.292115 | M23: 0.79725646 | N23: 13.30805 | O23: 0.63946439 | P23: 334.66864 | Q23: 0.55359629 | R23: 0.76249138 | S23: 0.23910316 | T23: 0.16132064 | U23: 97.647431 | V23: 523.43273 | W23: 0.43500682 | X23: 57.649246 | Y23: 2.8256102 | Z23: 0.77744309 | AA23: 8.0633905 | AB23: 0.39521763 | AC23: 0.15615184 | AD23: 203.51385 | AE23: 174.17068 | AF23: 320855 | AG23: 0.129 | AH23: 0.051650168 | AI23: 5.1531391 | AJ23: 0.26298032 | AK23: 0.53005205 | AL23: 2271.115 | AM23: 332.022 | AN23: 1.36 | AO23: 0.00081572655 | AP23: 5.93 | AQ23: 0.10550916 | AR23: 0.35469166 | AS23: 3.5087719 | AT23: 11.85 | AU23: 0.91285403 | AV23: 0.9206514 | AW23: 85.497359 | AX23: 9.6111599 | AY23: 115.33392 | AZ23: 76.59 | BA23: 21.399125 | BB23: 6.1685874 | BC23: 1.3591069 | BD23: 220.77871 | BE23: 0.4904 | BF23: 0.8182 | BG23: 0.6966 | BH23: 0.356 | BI23: 0.0134 | BJ23: 252.10576 | BK23: 255 | BL23: 0.52426238 | BM23: 19.381991 | BN23: 23.339 | BO23: 72.812 | BP23: 4.411 | BQ23: 146.4121 | BR23: 6.8456376 | BS23: 34.601889 | BT23: 11.973824 | BU23: 39.119429 | BV23: 0.37964656 | BW23: 0.036423841 | BX23: 0.0606729 | BY23: 0.490331 | BZ23: 3.37 | CA23: 2.34 | CB23: 0.0458 | CC23: 67.200842 | CD23: 6.4933894 | CE23: 15.816187 | CF23: 10.338033 | CG23: 0.68784237 | CH23: 21.954882 | CI23: 43.269857 | CJ23: 0.010465505 | CK23: 0.29517738 | CL23: 30.283051 | CM23: 26.869 | CN23: 5.6299888 | CO23: 0.344 | CP23: 0.442 | CQ23: 0.24530968 | CR23: 0.12265484 | CS23: 112.22918 | CT23: 0.006 | CU23: 0.52 | CV23: 25 | CW23: 0 | CX23: 0.61652889 | CY23: 3.0826445 | CZ23: 93.712392
A24: Norte de Santander | B24: 2019 | C24: 110.93117 | D24: 71.745998 | E24: 52.9725 | F24: 0.24815935 | G24: 0.014019202 | H24: 41.92 | I24: 59.43 | J24: 95.905705 | K24: 0.074770124 | L24: 35.664271 | M24: 1.5418764 | N24: 21.049964 | O24: 0.60328374 | P24: 468.84507 | Q24: 0.61313414 | R24: 0.85052791 | S24: 0.72502147 | T24: 0.61905764 | U24: 98.141035 | V24: 492.67708 | W24: 0.78384818 | X24: 81.432859 | Y24: 5.6086665 | Z24: 0.42858069 | AA24: 21.861702 | AB24: 1.5057189 | AC24: 0.097357428 | AD24: 184.06123 | AE24: 182.54351 | AF24: 909214 | AG24: 0.2514 | AH24: 0.094091261 | AI24: 7.0636987 | AJ24: 0.32110199 | AK24: 0.67936757 | AL24: 5643.528 | AM24: 686.011 | AN24: 2 | AO24: 0.0032918259 | AP24: 13.778 | AQ24: 0.30731527 | AR24: 0.3501505 | AS24: 4.4444444 | AT24: 11.8825 | AU24: 0.99987498 | AV24: 1 | AW24: 88.171581 | AX24: 9.936766 | AY24: 85.579803 | AZ24: 75.46 | BA24: 23.253725 | BB24: 4.7769415 | BC24: 1.3925143 | BD24: 191.79601 | BE24: 0.6588 | BF24: 0.9176 | BG24: 0.745 | BH24: 0.4056 | BI24: 0.0395 | BJ24: 258.12363 | BK24: 261 | BL24: 0.6181951 | BM24: 26.530975 | BN24: 41.819 | BO24: 109.971 | BP24: 10.847 | BQ24: 144.88283 | BR24: 6.7981791 | BS24: 9.5214851 | BT24: 11.316756 | BU24: 45.282041 | BV24: 0.38700418 | BW24: 0.010693215 | BX24: 0.0115219 | BY24: 0.0073139 | BZ24: 6.78 | CA24: 4.31 | CB24: 0.0449 | CC24: 58.907533 | CD24: 12.750299 | CE24: 19.759563 | CF24: 10.325177 | CG24: 0.68593419 | CH24: 22.33534 | CI24: 62.650829 | CJ24: 0.011681791 | CK24: 0.31457122 | CL24: 30.279221 | CM24: 26.843 | CN24: 6.4649026 | CO24: 0.09 | CP24: 0.506 | CQ24: 0.93853343 | CR24: 0.26815241 | CS24: 167.59526 | CT24: 0.004 | CU24: 0.21 | CV24: 15.09 | CW24: 0.69120538 | CX24: 3.4560269 | CY24: 2.7648215 | CZ24: 320.02809
A25: Putumayo | B25: 2019 | C25: 91.189349 | D25: 79.979075 | E25: 47.681429 | F25: 0.088545651 | G25: 0.00836182 | H25: 19.07 | I25: 91.03 | J25: 99.452041 | K25: 0.12615067 | L25: 45.952979 | M25: 1.4360306 | N25: 16.945161 | O25: 0.63531163 | P25: 334.87179 | Q25: 0.77570093 | R25: 0.48552531 | S25: 0.60278574 | T25: 0.64240196 | U25: 82.604396 | V25: 708.62722 | W25: 0.51493176 | X25: 147.31692 | Y25: 2.0612055 | Z25: 0.94218116 | AA25: 22.873095 | AB25: 0.32003215 | AC25: 0.40017579 | AD25: 492.35718 | AE25: 377.78693 | AF25: 34176 | AG25: 0 | AH25: 0.027410801 | AI25: 3.7434951 | AJ25: 0.20190179 | AK25: 0.44458164 | AL25: 754.055 | AM25: 225.047 | AN25: 0.5385 | AO25: 0.005485669 | AP25: 19.628 | AQ25: 0.12577708 | AR25: 0.28785972 | AS25: 0.93567251 | AT25: 6.2307692 | AU25: 0.91505043 | AV25: 0.9226597 | AW25: 83.382386 | AX25: 11.231006 | AY25: 44.043162 | AZ25: 73.83 | BA25: 21.28672 | BB25: 4.8421078 | BC25: 0.56561086 | BD25: 170.02602 | BE25: 0.4566 | BF25: 0.8071 | BG25: 0.7104 | BH25: 0.3659 | BI25: 0.0521 | BJ25: 242.76886 | BK25: 254 | BL25: 0.050427115 | BM25: 22.569751 | BN25: 3.527 | BO25: 6.75 | BP25: 8.705 | BQ25: 133.82814 | BR25: 0 | BS25: 8.9131423 | BT25: 2.5362319 | BU25: 7.6205288 | BV25: 0.43083276 | BW25: 0.0083194676 | BX25: 0.0212573 | BY25: 0.0566484 | BZ25: 5.66 | CA25: 3.21 | CB25: 0.0242 | CC25: 59.496235 | CD25: 13.181762 | CE25: 35.457374 | CF25: 3.2006897 | CG25: 0.41410057 | CH25: 16.195471 | CI25: 46.176145 | CJ25: 0.0026629937 | CK25: 0.16211352 | CL25: 28.697124 | CM25: 26.653 | CN25: 19.659587 | CO25: 0.349 | CP25: 1 | CQ25: 0 | CR25: 0 | CS25: 0 | CT25: 0.001 | CU25: 0 | CV25: 0 | CW25: 0 | CX25: 0 | CY25: 0 | CZ25: 52.824652
A26: Quindío | B26: 2019 | C26: 119.72882 | D26: 82.125734 | E26: 82.50875 | F26: 0.39692211 | G26: 0.015240856 | H26: 44.1 | I26: 47.095 | J26: 99.822784 | K26: 0.22895838 | L26: 39.26624 | M26: 0 | N26: 11.298305 | O26: 0.6347756 | P26: 511.25714 | Q26: 0.38842975 | R26: 0.96765105 | S26: 0.84398154 | T26: 0.85382407 | U26: 99.079541 | V26: 524.05442 | W26: 0.88712602 | X26: 35.932684 | Y26: 10.515014 | Z26: 0.65174206 | AA26: 44.026345 | AB26: 12.883469 | AC26: 0.42944889 | AD26: 451.13178 | AE26: 399.48844 | AF26: 387616 | AG26: 0.2414 | AH26: 0.1587122 | AI26: 5.7907821 | AJ26: 0.39758348 | AK26: 0.73075957 | AL26: 5724.24 | AM26: 646.025 | AN26: 1.15 | AO26: 0.00012860898 | AP26: 27.188 | AQ26: 0.40937646 | AR26: 0.17707016 | AS26: 3.3918129 | AT26: 16.5 | AU26: 0.97659144 | AV26: 0.93479718 | AW26: 93.233083 | AX26: 11.447121 | AY26: 34.170511 | AZ26: 75.16 | BA26: 28.371873 | BB26: 7.9053994 | BC26: 4.7896643 | BD26: 302.09074 | BE26: 0.6793 | BF26: 0.9526 | BG26: 0.8906 | BH26: 0.5466 | BI26: 0.0417 | BJ26: 259.66929 | BK26: 254 | BL26: 0.53673788 | BM26: 23.679393 | BN26: 35.724 | BO26: 53.374 | BP26: 24.404 | BQ26: 147.83433 | BR26: 6.3015312 | BS26: 50.292458 | BT26: 24.616457 | BU26: 71.582235 | BV26: 0.51088589 | BW26: 0.029547553 | BX26: 0.0394386 | BY26: 0.0616701 | BZ26: 8.71 | CA26: 5.27 | CB26: 0.0587 | CC26: 62.731802 | CD26: 13.659857 | CE26: 31.862864 | CF26: 11.482008 | CG26: 0.46690428 | CH26: 28.898069 | CI26: 77.550224 | CJ26: 0.018758208 | CK26: 0.35598293 | CL26: 29.586967 | CM26: 27.507 | CN26: 11.859113 | CO26: 0.295 | CP26: 0.982 | CQ26: 1.2965268 | CR26: 0 | CS26: 240.78355 | CT26: 0.003 | CU26: 0.88 | CV26: 16.67 | CW26: 13.109449 | CX26: 9.3638921 | CY26: 5.6183352 | CZ26: 569.32464
A27: Risaralda | B27: 2019 | C27: 130.25197 | D27: 74.700247 | E27: 73.806667 | F27: 0.40836343 | G27: 0.010639237 | H27: 64.77 | I27: 54.82 | J27: 92.255357 | K27: 0.2062096 | L27: 23.425881 | M27: 0.52999732 | N27: 11.977939 | O27: 0.52609857 | P27: 622.3617 | Q27: 0.68453378 | R27: 0.94042369 | S27: 0.77170322 | T27: n/a | U27: 99.675523 | V27: 466.38124 | W27: 0.8311866 | X27: 45.851022 | Y27: 10.448285 | Z27: 0.84456317 | AA27: 17.027118 | AB27: 3.8800483 | AC27: 0.20886612 | AD27: 419.65865 | AE27: 284.77545 | AF27: 1742190 | AG27: 0.2754 | AH27: 0.15578024 | AI27: 6.0568779 | AJ27: 0.45144131 | AK27: 0.77874369 | AL27: 10323.646 | AM27: 1269.485 | AN27: 1.6 | AO27: 9.419847e-05 | AP27: 21.768 | AQ27: 0.42783909 | AR27: 0.1743098 | AS27: 4.7953216 | AT27: 6.6857143 | AU27: 0.94202899 | AV27: 0.91289542 | AW27: 90.567113 | AX27: 11.078496 | AY27: 66.281602 | AZ27: 76.64 | BA27: 32.388063 | BB27: 9.6927386 | BC27: 6.3452186 | BD27: 235.53081 | BE27: 0.696 | BF27: 0.9623 | BG27: 0.8442 | BH27: 0.4919 | BI27: 0.0423 | BJ27: 259.38986 | BK27: 256 | BL27: 0.40294737 | BM27: 22.751489 | BN27: 42.592 | BO27: 223.383 | BP27: 19.88 | BQ27: 148.43533 | BR27: 7.7373974 | BS27: 48.159901 | BT27: 26.29784 | BU27: 44.890272 | BV27: 0.58367033 | BW27: 0.053558844 | BX27: 0.0247299 | BY27: 0.0395242 | BZ27: 7.31 | CA27: 7.05 | CB27: 0.0682 | CC27: 64.361578 | CD27: 7.8745848 | CE27: 34.441655 | CF27: 5.2056003 | CG27: 0.37900643 | CH27: 30.963336 | CI27: 81.828651 | CJ27: 0.026405993 | CK27: 0.39803017 | CL27: 30.329562 | CM27: 28.26 | CN27: 19.067224 | CO27: 0.186 | CP27: 0.572 | CQ27: 2.4379877 | CR27: 0.21199893 | CS27: 217.2989 | CT27: 0.004 | CU27: 1.07 | CV27: 18.62 | CW27: 4.2773246 | CX27: 6.4159869 | CY27: 16.039967 | CZ27: 982.71533
A28: Archipiélago de San Andrés | B28: 2019 | C28: 122.913 | D28: 39.860804 | E28: 71.24 | F28: 0.34498449 | G28: 0.035402096 | H28: 52.03 | I28: 55.95 | J28: 78.666169 | K28: 0.26731333 | L28: 42.428198 | M28: 0 | N28: 17.950392 | O28: 0.48422733 | P28: 259.29412 | Q28: 0.43181818 | R28: 0.50283231 | S28: - | T28: n/a | U28: 99.806392 | V28: 593.53487 | W28: 0.28434215 | X28: 74.654047 | Y28: 15.958075 | Z28: 0.86827839 | AA28: 35.80127 | AB28: 20.487505 | AC28: 0.75417646 | AD28: NA | AE28: - | AF28: 1983714 | AG28: 0.264 | AH28: 0.054051621 | AI28: 1.6827399 | AJ28: 0.36909532 | AK28: 0.77338454 | AL28: 6169.889 | AM28: 130.35 | AN28: 0.4444 | AO28: 0 | AP28: 2.249 | AQ28: 0.41256026 | AR28: 0.19504095 | AS28: 4.2105263 | AT28: 1.5 | AU28: 0.95060373 | AV28: 0.96528555 | AW28: 92.154567 | AX28: 25.761124 | AY28: 0 | AZ28: 74.67 | BA28: 53.684931 | BB28: 10.088334 | BC28: 2.0698197 | BD28: 279.047 | BE28: 0.6869 | BF28: 0.9296 | BG28: 0.8423 | BH28: 0.509 | BI28: 0.0197 | BJ28: 238 | BK28: 247 | BL28: 0.37075718 | BM28: 30.510811 | BN28: 1.441 | BO28: 16.311 | BP28: 26.589 | BQ28: 132.29815 | BR28: 40.740741 | BS28: 6.863418 | BT28: 26.618705 | BU28: 82.640145 | BV28: 0.73697917 | BW28: 0 | BX28: 0.243614 | BY28: 0.022234 | BZ28: 16.16 | CA28: 14.88 | CB28: 0.068 | CC28: 72.94158 | CD28: 7.3804738 | CE28: 58.619792 | CF28: 1.0646243 | CG28: 0.35211783 | CH28: 29.835345 | CI28: 105.43766 | CJ28: 0.0026334989 | CK28: 0.25532263 | CL28: 27.998685 | CM28: 0 | CN28: 0.93205029 | CO28: 1 | CP28: 1 | CQ28: 0 | CR28: 0 | CS28: 65.274151 | CT28: 0.006 | CU28: 0 | CV28: 0 | CW28: 16.310819 | CX28: 0 | CY28: 0 | CZ28: 1223.3114
A29: Santander | B29: 2019 | C29: 112.89371 | D29: 68.849706 | E29: 78.63375 | F29: 0.37421912 | G29: 0.0087799905 | H29: 42.46 | I29: 55.11 | J29: 94.428537 | K29: 0.084975319 | L29: 11.213651 | M29: 0.13731001 | N29: 9.794781 | O29: 0.50326567 | P29: 389.46349 | Q29: 0.51980485 | R29: 0.82458737 | S29: 0.83850277 | T29: 0.22516417 | U29: 99.520925 | V29: 461.45612 | W29: 0.76065828 | X29: 82.266915 | Y29: 5.8859678 | Z29: 0.81469627 | AA29: 24.098831 | AB29: 1.724204 | AC29: 0.2397777 | AD29: 270.00979 | AE29: 228.92022 | AF29: 1595907 | AG29: 0.2756 | AH29: 0.15785766 | AI29: 6.0327893 | AJ29: 0.39957684 | AK29: 0.73688093 | AL29: 6341.352 | AM29: 930.326 | AN29: 2.6341 | AO29: 0.00086613046 | AP29: 26.589 | AQ29: 0.45095195 | AR29: 0.18638076 | AS29: 0.70175439 | AT29: 8.2517241 | AU29: 0.89882184 | AV29: 0.89081445 | AW29: 92.149489 | AX29: 5.6549797 | AY29: 49.89688 | AZ29: 78.3 | BA29: 42.163179 | BB29: 8.8280217 | BC29: 4.2538659 | BD29: 257.54782 | BE29: 0.6751 | BF29: 0.9488 | BG29: 0.8383 | BH29: 0.4963 | BI29: 0.032 | BJ29: 270.72616 | BK29: 268 | BL29: 0.50265322 | BM29: 21.668793 | BN29: 37.68 | BO29: 330.958 | BP29: 23.143 | BQ29: 152.29188 | BR29: 7.3492083 | BS29: 36.703556 | BT29: 26.410486 | BU29: 50.103764 | BV29: 0.51153888 | BW29: 0.036775571 | BX29: 0.0123496 | BY29: 0.0040818 | BZ29: 8.25 | CA29: 8.05 | CB29: 0.057 | CC29: 67.330537 | CD29: 9.6036375 | CE29: 32.302158 | CF29: 7.8177406 | CG29: 0.51367453 | CH29: 37.948442 | CI29: 86.366228 | CJ29: 0.012671403 | CK29: 0.2759738 | CL29: 31.703195 | CM29: 28.266 | CN29: 6.2302181 | CO29: 0.233 | CP29: 0.281 | CQ29: 2.7919703 | CR29: 0.45770005 | CS29: 298.42043 | CT29: 0.008 | CU29: 0.99 | CV29: 21.78 | CW29: 8.8516354 | CX29: 4.6587555 | CY29: 6.5222577 | CZ29: 676.91717
A30: Sucre | B30: 2019 | C30: 92.030256 | D30: 76.325314 | E30: 43.035 | F30: 0.18697712 | G30: 0.01410738 | H30: 53.26 | I30: 44.185 | J30: 98.13895 | K30: 0.13624799 | L30: 16.356067 | M30: 0 | N30: 9.5042012 | O30: 0.50719397 | P30: 305.09091 | Q30: 0.52641879 | R30: 0.85833787 | S30: 0.89464363 | T30: n/a | U30: 97.644088 | V30: 426.51937 | W30: 0.59222139 | X30: 49.927779 | Y30: 4.1382981 | Z30: 1 | AA30: 9.8811629 | AB30: 0.81900693 | AC30: 0 | AD30: 292.94556 | AE30: 314.91685 | AF30: 93063 | AG30: 0.1116 | AH30: 0.054398817 | AI30: 4.8063447 | AJ30: 0.19657754 | AK30: 0.48424301 | AL30: 1567.517 | AM30: 317.425 | AN30: 1.1905 | AO30: 7.8780865e-05 | AP30: 1.496 | AQ30: 0.33312271 | AR30: 0.093757272 | AS30: 0.58479532 | AT30: 15.053846 | AU30: 0.93734909 | AV30: 0.92136067 | AW30: 87.889564 | AX30: 11.766988 | AY30: 77.584535 | AZ30: 76.14 | BA30: 19.487188 | BB30: 5.2302435 | BC30: 1.6526156 | BD30: 314.96481 | BE30: 0.7216 | BF30: 0.9533 | BG30: 0.7531 | BH30: 0.4167 | BI30: 0.0278 | BJ30: 237 | BK30: 241 | BL30: 0.30492333 | BM30: 25.270655 | BN30: 25.615 | BO30: 29.033 | BP30: 5.398 | BQ30: 140.9543 | BR30: 5.1899907 | BS30: 5.2638239 | BT30: 10.17316 | BU30: 32.900475 | BV30: 0.29774436 | BW30: 0.0075244545 | BX30: 0.019493 | BY30: 0.0500241 | BZ30: 4.46 | CA30: 2.76 | CB30: 0.0429 | CC30: 68.381111 | CD30: 8.8268112 | CE30: 14.973001 | CF30: 10.260391 | CG30: 0.67812322 | CH30: 23.945114 | CI30: 31.96698 | CJ30: 0.0049791056 | CK30: 0.20793924 | CL30: 29.305731 | CM30: 28.275 | CN30: 31.052817 | CO30: 0.338 | CP30: 0.98 | CQ30: 0.55256984 | CR30: 0 | CS30: 99.462571 | CT30: 0.001 | CU30: 0.61 | CV30: 18.19 | CW30: 0 | CX30: 0 | CY30: 0 | CZ30: 54.015246
A31: Tolima | B31: 2019 | C31: 122.21172 | D31: 67.077971 | E31: 59.125 | F31: 0.23045368 | G31: 0.010182753 | H31: 36.09 | I31: 92.31 | J31: 93.558366 | K31: 0.15838056 | L31: 20.673785 | M31: 0.2255322 | N31: 15.33619 | O31: 0.50714815 | P31: 341.41237 | Q31: 0.64402367 | R31: 0.8549436 | S31: 0.76207586 | T31: 0.081851574 | U31: 98.306345 | V31: 464.67532 | W31: 0.71978111 | X31: 73.134228 | Y31: 4.1287751 | Z31: 0.87467979 | AA31: 61.537212 | AB31: 3.4740684 | AC31: 0.30228694 | AD31: 244.36683 | AE31: 195.15172 | AF31: 125335 | AG31: 0.2258 | AH31: 0.10386379 | AI31: 5.4056544 | AJ31: 0.32645871 | AK31: 0.67995856 | AL31: 4721.137 | AM31: 1152.753 | AN31: 2 | AO31: 0.00011074535 | AP31: 11.22 | AQ31: 0.3762894 | AR31: 0.22538158 | AS31: 4.7953216 | AT31: 4.6106383 | AU31: 0.92524987 | AV31: 0.8886354 | AW31: 89.486539 | AX31: 7.9100514 | AY31: 79.100514 | AZ31: 76.55 | BA31: 24.922109 | BB31: 5.8013047 | BC31: 2.0440966 | BD31: 220.26978 | BE31: 0.7209 | BF31: 0.982 | BG31: 0.8351 | BH31: 0.4672 | BI31: 0.0302 | BJ31: 246.71335 | BK31: 247.97215 | BL31: 0.48032013 | BM31: 23.447957 | BN31: 25.974 | BO31: 68.24 | BP31: 18.638 | BQ31: 144.63853 | BR31: 7.892204 | BS31: 41.677307 | BT31: 14.597262 | BU31: 28.673394 | BV31: 0.41854637 | BW31: 0.0097765363 | BX31: 0.0193086 | BY31: 0.0520908 | BZ31: 6.41 | CA31: 4.4 | CB31: 0.0364 | CC31: 64.253284 | CD31: 14.130461 | CE31: 25.162402 | CF31: 11.676112 | CG31: 0.45585944 | CH31: 34.316315 | CI31: 74.919667 | CJ31: 0.0097594702 | CK31: 0.32652208 | CL31: 30.605402 | CM31: 26.849 | CN31: 2.7542179 | CO31: 0.25 | CP31: 0.542 | CQ31: 0.8269514 | CR31: 0 | CS31: 130.0569 | CT31: 0.004 | CU31: 0.97 | CV31: 25.61 | CW31: 1.5080648 | CX31: 1.5080648 | CY31: 2.2620971 | CZ31: 318.20166
A32: Valle del Cauca | B32: 2019 | C32: 164.37937 | D32: 74.622173 | E32: 68.97 | F32: 0.43711545 | G32: 0.0098118857 | H32: 56.58 | I32: 87.21 | J32: 98.214253 | K32: 0.2937399 | L32: 50.64919 | M32: 0.33512918 | N32: 15.304233 | O32: 0.55186344 | P32: 481.81905 | Q32: 0.47970564 | R32: 0.95725696 | S32: 1 | T32: 0.043203717 | U32: 99.272399 | V32: 457.2777 | W32: 0.89236648 | X32: 29.258967 | Y32: 5.9150768 | Z32: 0.76274968 | AA32: 18.351658 | AB32: 3.710024 | AC32: 0.45989721 | AD32: 289.85646 | AE32: 245.79219 | AF32: 4647659 | AG32: 0.373 | AH32: 0.15017325 | AI32: 5.8844799 | AJ32: 0.47339746 | AK32: 0.80063697 | AL32: 4343.63 | AM32: 648.206 | AN32: 2.0308 | AO32: 0.00014668495 | AP32: 23.142 | AQ32: 0.51330236 | AR32: 0.19939801 | AS32: 8.7719298 | AT32: 17.840476 | AU32: 0.94257355 | AV32: 0.92691051 | AW32: 91.086443 | AX32: 10.050349 | AY32: 42.602634 | AZ32: 75.53 | BA32: 38.91637 | BB32: 8.8982639 | BC32: 4.39454 | BD32: 232.4456 | BE32: 0.5398 | BF32: 0.7619 | BG32: 0.7145 | BH32: 0.402 | BI32: 0.0326 | BJ32: 256.30779 | BK32: 250 | BL32: 0.25354251 | BM32: 27.337256 | BN32: 30.116 | BO32: 115.802 | BP32: 15.7 | BQ32: 149.33876 | BR32: 11.083951 | BS32: 43.223657 | BT32: 26.40072 | BU32: 28.294518 | BV32: 0.57842513 | BW32: 0.056931998 | BX32: 0.011935 | BY32: 0.0069854 | BZ32: 10.33 | CA32: 8.75 | CB32: 0.0653 | CC32: 65.263278 | CD32: 12.11556 | CE32: 36.424201 | CF32: 11.408238 | CG32: 0.39352299 | CH32: 39.774143 | CI32: 81.014931 | CJ32: 0.022722992 | CK32: 0.43193301 | CL32: 32.184256 | CM32: 29.125 | CN32: 17.485041 | CO32: 0.102 | CP32: 0.036 | CQ32: 3.2395821 | CR32: 0.31278723 | CS32: 253.35766 | CT32: 0.006 | CU32: 1.07 | CV32: 23.22 | CW32: 5.1888879 | CX32: 6.0913032 | CY32: 13.761833 | CZ32: 1143.3602
A33: Vaupés | B33: 2019 | C33: 93.336924 | D33: 59.515174 | E33: 42.608571 | F33: 0.061523909 | G33: 0.029323731 | H33: 54.52 | I33: 93.02 | J33: 96.940973 | K33: 0.0012357121 | L33: 7.3534819 | M33: 0 | N33: 7.3534819 | O33: n/a | P33: n/a | Q33: 1 | R33: 0.40757993 | S33: - | T33: n/a | U33: 58.050665 | V33: 608.91108 | W33: 0.35686799 | X33: - | Y33: - | Z33: - | AA33: 62.043778 | AB33: 0.046757181 | AC33: 0 | AD33: NA | AE33: - | AF33: 29768 | AG33: 0.0198 | AH33: 0.0014606742 | AI33: 2.0644154 | AJ33: 0.11855972 | AK33: 0.19856341 | AL33: 0 | AM33: 0 | AN33: 0 | AO33: 0.00019716295 | AP33: 10.615 | AQ33: 0.36399552 | AR33: 0.070092901 | AS33: 1.1695906 | AT33: 6.7666667 | AU33: 0.86542923 | AV33: 0.83513839 | AW33: 37.943262 | AX33: 10.118044 | AY33: 0 | AZ33: 63.93 | BA33: 13.139892 | BB33: 1.7812427 | BC33: 0.41304179 | BD33: 49.023212 | BE33: 0.2282 | BF33: 0.5112 | BG33: 0.3054 | BH33: 0.1135 | BI33: 0.0388 | BJ33: 212 | BK33: 223 | BL33: 0.16111111 | BM33: 27.017647 | BN33: 1.007 | BO33: 0 | BP33: 4.338 | BQ33: 132.63913 | BR33: 0 | BS33: 15.853659 | BT33: 0 | BU33: 0 | BV33: 0.33 | BW33: 0.011695906 | BX33: 0.56299069 | BY33: 0.0581058 | BZ33: 2.94 | CA33: 0.98 | CB33: 0 | CC33: 49.090899 | CD33: 8.0178323 | CE33: 49.73976 | CF33: 1.8365504 | CG33: 0.45411235 | CH33: 14.521375 | CI33: 27.753253 | CJ33: 0.0092724848 | CK33: 0.024149309 | CL33: 26.294629 | CM33: 17.93 | CN33: 0.11150923 | CO33: 1 | CP33: 1 | CQ33: 0 | CR33: 0 | CS33: 24.511606 | CT33: 0.017 | CU33: 0 | CV33: 0 | CW33: 0 | CX33: 0 | CY33: 0 | CZ33: 25.118686
